2023-08-19 20:06:39,454 ERROR: Start logging API services at the error level. [in /home/minhmannh2001/Documents/CodeSpace/discover_quest/user_management_service/app/__init__.py:55]
2023-08-19 20:10:36,603 ERROR: Start logging API services at the error level. [in /home/minhmannh2001/Documents/CodeSpace/discover_quest/user_management_service/app/__init__.py:55]
2023-08-19 20:51:56,250 ERROR: Start logging API services at the error level. [in /home/minhmannh2001/Documents/CodeSpace/discover_quest/user_management_service/app/__init__.py:55]
2023-08-19 23:47:03,572 ERROR: Start logging API services at the error level. [in /home/minhmannh2001/Documents/CodeSpace/discover_quest/user_management_service/app/__init__.py:55]
2023-08-23 21:42:46,328 ERROR: Start logging API services at the error level. [in /home/minhmannh2001/Documents/CodeSpace/discover_quest/user_management_service/app/__init__.py:58]
2023-08-23 21:44:08,511 ERROR: Start logging API services at the error level. [in /home/minhmannh2001/Documents/CodeSpace/discover_quest/user_management_service/app/__init__.py:58]
2023-08-23 21:46:02,720 ERROR: Start logging API services at the error level. [in /home/minhmannh2001/Documents/CodeSpace/discover_quest/user_management_service/app/__init__.py:58]
2023-08-23 21:46:21,207 ERROR: Start logging API services at the error level. [in /home/minhmannh2001/Documents/CodeSpace/discover_quest/user_management_service/app/__init__.py:58]
2023-08-23 21:48:04,087 ERROR: Start logging API services at the error level. [in /home/minhmannh2001/Documents/CodeSpace/discover_quest/user_management_service/app/__init__.py:58]
2023-08-23 21:48:46,640 ERROR: Start logging API services at the error level. [in /home/minhmannh2001/Documents/CodeSpace/discover_quest/user_management_service/app/__init__.py:57]
2023-08-24 01:57:33,917 ERROR: Start logging API services at the error level. [in /home/minhmannh2001/Documents/CodeSpace/discover_quest/user_management_service/app/__init__.py:57]
2023-08-24 01:58:12,181 ERROR: Start logging API services at the error level. [in /home/minhmannh2001/Documents/CodeSpace/discover_quest/user_management_service/app/__init__.py:57]
2023-08-24 01:59:33,517 ERROR: Start logging API services at the error level. [in /home/minhmannh2001/Documents/CodeSpace/discover_quest/user_management_service/app/__init__.py:57]
2023-08-24 01:59:50,313 ERROR: Start logging API services at the error level. [in /home/minhmannh2001/Documents/CodeSpace/discover_quest/user_management_service/app/__init__.py:57]
2023-08-24 02:01:14,532 ERROR: Start logging API services at the error level. [in /home/minhmannh2001/Documents/CodeSpace/discover_quest/user_management_service/app/__init__.py:57]
2023-08-24 02:02:19,058 ERROR: Start logging API services at the error level. [in /home/minhmannh2001/Documents/CodeSpace/discover_quest/user_management_service/app/__init__.py:57]
2023-08-24 02:03:20,516 ERROR: Start logging API services at the error level. [in /home/minhmannh2001/Documents/CodeSpace/discover_quest/user_management_service/app/__init__.py:57]
2023-08-24 02:05:28,455 ERROR: Start logging API services at the error level. [in /home/minhmannh2001/Documents/CodeSpace/discover_quest/user_management_service/app/__init__.py:58]
2023-08-24 02:11:50,507 ERROR: Start logging API services at the error level. [in /home/minhmannh2001/Documents/CodeSpace/discover_quest/user_management_service/app/__init__.py:58]
2023-08-24 02:42:17,091 ERROR: Start logging API services at the error level. [in /home/minhmannh2001/Documents/CodeSpace/discover_quest/user_management_service/app/__init__.py:58]
2023-08-24 20:23:52,271 ERROR: Start logging API services at the error level. [in /home/minhmannh2001/Documents/CodeSpace/discover_quest/user_management_service/app/__init__.py:58]
2023-08-24 20:32:19,633 ERROR: Start logging API services at the error level. [in /home/minhmannh2001/Documents/CodeSpace/discover_quest/user_management_service/app/__init__.py:58]
2023-08-24 20:32:57,763 ERROR: Start logging API services at the error level. [in /home/minhmannh2001/Documents/CodeSpace/discover_quest/user_management_service/app/__init__.py:58]
2023-08-24 22:59:19,241 ERROR: Start logging API services at the error level. [in /home/minhmannh2001/Documents/CodeSpace/discover_quest/user_management_service/app/__init__.py:68]
2023-08-24 23:03:30,110 ERROR: Exception on /v1/user [POST] [in /home/minhmannh2001/Documents/CodeSpace/discover_quest/user_management_service/venv/lib/python3.8/site-packages/flask/app.py:1744]
Traceback (most recent call last):
  File "/home/minhmannh2001/Documents/CodeSpace/discover_quest/user_management_service/venv/lib/python3.8/site-packages/flask/app.py", line 2529, in wsgi_app
    response = self.full_dispatch_request()
  File "/home/minhmannh2001/Documents/CodeSpace/discover_quest/user_management_service/venv/lib/python3.8/site-packages/flask/app.py", line 1825, in full_dispatch_request
    rv = self.handle_user_exception(e)
  File "/home/minhmannh2001/Documents/CodeSpace/discover_quest/user_management_service/venv/lib/python3.8/site-packages/flask/app.py", line 1823, in full_dispatch_request
    rv = self.dispatch_request()
  File "/home/minhmannh2001/Documents/CodeSpace/discover_quest/user_management_service/venv/lib/python3.8/site-packages/flask/app.py", line 1799, in dispatch_request
    return self.ensure_sync(self.view_functions[rule.endpoint])(**view_args)
  File "/home/minhmannh2001/Documents/CodeSpace/discover_quest/user_management_service/venv/lib/python3.8/site-packages/connexion/decorators/decorator.py", line 68, in wrapper
    response = function(request)
  File "/home/minhmannh2001/Documents/CodeSpace/discover_quest/user_management_service/venv/lib/python3.8/site-packages/connexion/security/security_handler_factory.py", line 380, in wrapper
    cls._raise_most_specific(errors)
  File "/home/minhmannh2001/Documents/CodeSpace/discover_quest/user_management_service/venv/lib/python3.8/site-packages/connexion/security/security_handler_factory.py", line 421, in _raise_most_specific
    raise status_to_exc[lowest_status_code]
  File "/home/minhmannh2001/Documents/CodeSpace/discover_quest/user_management_service/venv/lib/python3.8/site-packages/connexion/security/security_handler_factory.py", line 372, in wrapper
    token_info = func(request)
  File "/home/minhmannh2001/Documents/CodeSpace/discover_quest/user_management_service/venv/lib/python3.8/site-packages/connexion/security/security_handler_factory.py", line 255, in wrapper
    return check_api_key_func(request, api_key)
  File "/home/minhmannh2001/Documents/CodeSpace/discover_quest/user_management_service/venv/lib/python3.8/site-packages/connexion/security/security_handler_factory.py", line 322, in wrapper
    token_info = func(*args, **kwargs)
  File "/home/minhmannh2001/Documents/CodeSpace/discover_quest/user_management_service/helpers/utils.py", line 36, in decode_token
    return flask_jwt_extended.decode_token(token[7:])
  File "/home/minhmannh2001/Documents/CodeSpace/discover_quest/user_management_service/venv/lib/python3.8/site-packages/flask_jwt_extended/utils.py", line 128, in decode_token
    return jwt_manager._decode_jwt_from_config(encoded_token, csrf_value, allow_expired)
  File "/home/minhmannh2001/Documents/CodeSpace/discover_quest/user_management_service/venv/lib/python3.8/site-packages/flask_jwt_extended/jwt_manager.py", line 541, in _decode_jwt_from_config
    secret = self._decode_key_callback(unverified_headers, unverified_claims)
  File "/home/minhmannh2001/Documents/CodeSpace/discover_quest/user_management_service/venv/lib/python3.8/site-packages/flask_jwt_extended/default_callbacks.py", line 153, in default_decode_key_callback
    return config.decode_key
  File "/home/minhmannh2001/Documents/CodeSpace/discover_quest/user_management_service/venv/lib/python3.8/site-packages/flask_jwt_extended/config.py", line 40, in decode_key
    return self._public_key if self.is_asymmetric else self._secret_key
  File "/home/minhmannh2001/Documents/CodeSpace/discover_quest/user_management_service/venv/lib/python3.8/site-packages/flask_jwt_extended/config.py", line 249, in _public_key
    raise RuntimeError(
RuntimeError: JWT_PUBLIC_KEY must be set to use asymmetric cryptography algorithm "RS256"
2023-08-24 23:04:12,256 ERROR: Start logging API services at the error level. [in /home/minhmannh2001/Documents/CodeSpace/discover_quest/user_management_service/app/__init__.py:68]
2023-08-24 23:08:17,049 ERROR: Start logging API services at the error level. [in /home/minhmannh2001/Documents/CodeSpace/discover_quest/user_management_service/app/__init__.py:68]
2023-08-24 23:08:18,806 ERROR: Exception on /v1/user [POST] [in /home/minhmannh2001/Documents/CodeSpace/discover_quest/user_management_service/venv/lib/python3.8/site-packages/flask/app.py:1744]
Traceback (most recent call last):
  File "/home/minhmannh2001/Documents/CodeSpace/discover_quest/user_management_service/venv/lib/python3.8/site-packages/flask/app.py", line 2529, in wsgi_app
    response = self.full_dispatch_request()
  File "/home/minhmannh2001/Documents/CodeSpace/discover_quest/user_management_service/venv/lib/python3.8/site-packages/flask/app.py", line 1825, in full_dispatch_request
    rv = self.handle_user_exception(e)
  File "/home/minhmannh2001/Documents/CodeSpace/discover_quest/user_management_service/venv/lib/python3.8/site-packages/flask/app.py", line 1823, in full_dispatch_request
    rv = self.dispatch_request()
  File "/home/minhmannh2001/Documents/CodeSpace/discover_quest/user_management_service/venv/lib/python3.8/site-packages/flask/app.py", line 1799, in dispatch_request
    return self.ensure_sync(self.view_functions[rule.endpoint])(**view_args)
  File "/home/minhmannh2001/Documents/CodeSpace/discover_quest/user_management_service/venv/lib/python3.8/site-packages/connexion/decorators/decorator.py", line 68, in wrapper
    response = function(request)
  File "/home/minhmannh2001/Documents/CodeSpace/discover_quest/user_management_service/venv/lib/python3.8/site-packages/connexion/security/security_handler_factory.py", line 388, in wrapper
    return function(request)
  File "/home/minhmannh2001/Documents/CodeSpace/discover_quest/user_management_service/venv/lib/python3.8/site-packages/connexion/decorators/uri_parsing.py", line 149, in wrapper
    response = function(request)
  File "/home/minhmannh2001/Documents/CodeSpace/discover_quest/user_management_service/venv/lib/python3.8/site-packages/connexion/decorators/validation.py", line 196, in wrapper
    response = function(request)
  File "/home/minhmannh2001/Documents/CodeSpace/discover_quest/user_management_service/venv/lib/python3.8/site-packages/connexion/decorators/validation.py", line 399, in wrapper
    return function(request)
  File "/home/minhmannh2001/Documents/CodeSpace/discover_quest/user_management_service/venv/lib/python3.8/site-packages/connexion/decorators/parameter.py", line 120, in wrapper
    return function(**kwargs)
  File "/home/minhmannh2001/Documents/CodeSpace/discover_quest/user_management_service/app/controllers/user_controller.py", line 3, in create_user
    cleaned_data = validate(["email", "username", "password", "confirm_password"], user)
  File "/home/minhmannh2001/Documents/CodeSpace/discover_quest/user_management_service/app/controllers/user_controller.py", line 32, in validate
    for key, value in user_data.items():
AttributeError: 'str' object has no attribute 'items'
2023-08-24 23:09:49,432 ERROR: Exception on /v1/user [POST] [in /home/minhmannh2001/Documents/CodeSpace/discover_quest/user_management_service/venv/lib/python3.8/site-packages/flask/app.py:1744]
Traceback (most recent call last):
  File "/home/minhmannh2001/Documents/CodeSpace/discover_quest/user_management_service/venv/lib/python3.8/site-packages/flask/app.py", line 2529, in wsgi_app
    response = self.full_dispatch_request()
  File "/home/minhmannh2001/Documents/CodeSpace/discover_quest/user_management_service/venv/lib/python3.8/site-packages/flask/app.py", line 1825, in full_dispatch_request
    rv = self.handle_user_exception(e)
  File "/home/minhmannh2001/Documents/CodeSpace/discover_quest/user_management_service/venv/lib/python3.8/site-packages/flask/app.py", line 1823, in full_dispatch_request
    rv = self.dispatch_request()
  File "/home/minhmannh2001/Documents/CodeSpace/discover_quest/user_management_service/venv/lib/python3.8/site-packages/flask/app.py", line 1799, in dispatch_request
    return self.ensure_sync(self.view_functions[rule.endpoint])(**view_args)
  File "/home/minhmannh2001/Documents/CodeSpace/discover_quest/user_management_service/venv/lib/python3.8/site-packages/connexion/decorators/decorator.py", line 68, in wrapper
    response = function(request)
  File "/home/minhmannh2001/Documents/CodeSpace/discover_quest/user_management_service/venv/lib/python3.8/site-packages/connexion/security/security_handler_factory.py", line 388, in wrapper
    return function(request)
  File "/home/minhmannh2001/Documents/CodeSpace/discover_quest/user_management_service/venv/lib/python3.8/site-packages/connexion/decorators/uri_parsing.py", line 149, in wrapper
    response = function(request)
  File "/home/minhmannh2001/Documents/CodeSpace/discover_quest/user_management_service/venv/lib/python3.8/site-packages/connexion/decorators/validation.py", line 196, in wrapper
    response = function(request)
  File "/home/minhmannh2001/Documents/CodeSpace/discover_quest/user_management_service/venv/lib/python3.8/site-packages/connexion/decorators/validation.py", line 399, in wrapper
    return function(request)
  File "/home/minhmannh2001/Documents/CodeSpace/discover_quest/user_management_service/venv/lib/python3.8/site-packages/connexion/decorators/parameter.py", line 120, in wrapper
    return function(**kwargs)
  File "/home/minhmannh2001/Documents/CodeSpace/discover_quest/user_management_service/app/controllers/user_controller.py", line 3, in create_user
    cleaned_data = validate(["email", "username", "password", "confirm_password"], user)
  File "/home/minhmannh2001/Documents/CodeSpace/discover_quest/user_management_service/app/controllers/user_controller.py", line 32, in validate
    for key, value in user_data.items():
AttributeError: 'str' object has no attribute 'items'
2023-08-24 23:12:02,382 ERROR: Exception on /v1/user [POST] [in /home/minhmannh2001/Documents/CodeSpace/discover_quest/user_management_service/venv/lib/python3.8/site-packages/flask/app.py:1744]
Traceback (most recent call last):
  File "/home/minhmannh2001/Documents/CodeSpace/discover_quest/user_management_service/venv/lib/python3.8/site-packages/flask/app.py", line 2529, in wsgi_app
    response = self.full_dispatch_request()
  File "/home/minhmannh2001/Documents/CodeSpace/discover_quest/user_management_service/venv/lib/python3.8/site-packages/flask/app.py", line 1825, in full_dispatch_request
    rv = self.handle_user_exception(e)
  File "/home/minhmannh2001/Documents/CodeSpace/discover_quest/user_management_service/venv/lib/python3.8/site-packages/flask/app.py", line 1823, in full_dispatch_request
    rv = self.dispatch_request()
  File "/home/minhmannh2001/Documents/CodeSpace/discover_quest/user_management_service/venv/lib/python3.8/site-packages/flask/app.py", line 1799, in dispatch_request
    return self.ensure_sync(self.view_functions[rule.endpoint])(**view_args)
  File "/home/minhmannh2001/Documents/CodeSpace/discover_quest/user_management_service/venv/lib/python3.8/site-packages/connexion/decorators/decorator.py", line 68, in wrapper
    response = function(request)
  File "/home/minhmannh2001/Documents/CodeSpace/discover_quest/user_management_service/venv/lib/python3.8/site-packages/connexion/security/security_handler_factory.py", line 388, in wrapper
    return function(request)
  File "/home/minhmannh2001/Documents/CodeSpace/discover_quest/user_management_service/venv/lib/python3.8/site-packages/connexion/decorators/uri_parsing.py", line 149, in wrapper
    response = function(request)
  File "/home/minhmannh2001/Documents/CodeSpace/discover_quest/user_management_service/venv/lib/python3.8/site-packages/connexion/decorators/validation.py", line 196, in wrapper
    response = function(request)
  File "/home/minhmannh2001/Documents/CodeSpace/discover_quest/user_management_service/venv/lib/python3.8/site-packages/connexion/decorators/validation.py", line 399, in wrapper
    return function(request)
  File "/home/minhmannh2001/Documents/CodeSpace/discover_quest/user_management_service/venv/lib/python3.8/site-packages/connexion/decorators/parameter.py", line 120, in wrapper
    return function(**kwargs)
  File "/home/minhmannh2001/Documents/CodeSpace/discover_quest/user_management_service/app/controllers/user_controller.py", line 3, in create_user
    cleaned_data = validate(["email", "username", "password", "confirm_password"], user)
  File "/home/minhmannh2001/Documents/CodeSpace/discover_quest/user_management_service/app/controllers/user_controller.py", line 32, in validate
    for key, value in user_data.items():
AttributeError: 'str' object has no attribute 'items'
2023-08-24 23:14:27,185 ERROR: Start logging API services at the error level. [in /home/minhmannh2001/Documents/CodeSpace/discover_quest/user_management_service/app/__init__.py:68]
2023-08-24 23:15:06,359 ERROR: Exception on /v1/user [POST] [in /home/minhmannh2001/Documents/CodeSpace/discover_quest/user_management_service/venv/lib/python3.8/site-packages/flask/app.py:1744]
Traceback (most recent call last):
  File "/home/minhmannh2001/Documents/CodeSpace/discover_quest/user_management_service/venv/lib/python3.8/site-packages/flask/app.py", line 2529, in wsgi_app
    response = self.full_dispatch_request()
  File "/home/minhmannh2001/Documents/CodeSpace/discover_quest/user_management_service/venv/lib/python3.8/site-packages/flask/app.py", line 1825, in full_dispatch_request
    rv = self.handle_user_exception(e)
  File "/home/minhmannh2001/Documents/CodeSpace/discover_quest/user_management_service/venv/lib/python3.8/site-packages/flask/app.py", line 1823, in full_dispatch_request
    rv = self.dispatch_request()
  File "/home/minhmannh2001/Documents/CodeSpace/discover_quest/user_management_service/venv/lib/python3.8/site-packages/flask/app.py", line 1799, in dispatch_request
    return self.ensure_sync(self.view_functions[rule.endpoint])(**view_args)
  File "/home/minhmannh2001/Documents/CodeSpace/discover_quest/user_management_service/venv/lib/python3.8/site-packages/connexion/decorators/decorator.py", line 68, in wrapper
    response = function(request)
  File "/home/minhmannh2001/Documents/CodeSpace/discover_quest/user_management_service/venv/lib/python3.8/site-packages/connexion/security/security_handler_factory.py", line 388, in wrapper
    return function(request)
  File "/home/minhmannh2001/Documents/CodeSpace/discover_quest/user_management_service/venv/lib/python3.8/site-packages/connexion/decorators/uri_parsing.py", line 149, in wrapper
    response = function(request)
  File "/home/minhmannh2001/Documents/CodeSpace/discover_quest/user_management_service/venv/lib/python3.8/site-packages/connexion/decorators/validation.py", line 196, in wrapper
    response = function(request)
  File "/home/minhmannh2001/Documents/CodeSpace/discover_quest/user_management_service/venv/lib/python3.8/site-packages/connexion/decorators/validation.py", line 399, in wrapper
    return function(request)
  File "/home/minhmannh2001/Documents/CodeSpace/discover_quest/user_management_service/venv/lib/python3.8/site-packages/connexion/decorators/parameter.py", line 120, in wrapper
    return function(**kwargs)
  File "/home/minhmannh2001/Documents/CodeSpace/discover_quest/user_management_service/app/controllers/user_controller.py", line 3, in create_user
    cleaned_data = validate(["email", "username", "password", "confirm_password"], user)
  File "/home/minhmannh2001/Documents/CodeSpace/discover_quest/user_management_service/app/controllers/user_controller.py", line 32, in validate
    for key, value in user_data.items():
AttributeError: 'str' object has no attribute 'items'
2023-08-24 23:15:17,512 ERROR: Exception on /v1/user [POST] [in /home/minhmannh2001/Documents/CodeSpace/discover_quest/user_management_service/venv/lib/python3.8/site-packages/flask/app.py:1744]
Traceback (most recent call last):
  File "/home/minhmannh2001/Documents/CodeSpace/discover_quest/user_management_service/venv/lib/python3.8/site-packages/flask/app.py", line 2529, in wsgi_app
    response = self.full_dispatch_request()
  File "/home/minhmannh2001/Documents/CodeSpace/discover_quest/user_management_service/venv/lib/python3.8/site-packages/flask/app.py", line 1825, in full_dispatch_request
    rv = self.handle_user_exception(e)
  File "/home/minhmannh2001/Documents/CodeSpace/discover_quest/user_management_service/venv/lib/python3.8/site-packages/flask/app.py", line 1823, in full_dispatch_request
    rv = self.dispatch_request()
  File "/home/minhmannh2001/Documents/CodeSpace/discover_quest/user_management_service/venv/lib/python3.8/site-packages/flask/app.py", line 1799, in dispatch_request
    return self.ensure_sync(self.view_functions[rule.endpoint])(**view_args)
  File "/home/minhmannh2001/Documents/CodeSpace/discover_quest/user_management_service/venv/lib/python3.8/site-packages/connexion/decorators/decorator.py", line 68, in wrapper
    response = function(request)
  File "/home/minhmannh2001/Documents/CodeSpace/discover_quest/user_management_service/venv/lib/python3.8/site-packages/connexion/security/security_handler_factory.py", line 388, in wrapper
    return function(request)
  File "/home/minhmannh2001/Documents/CodeSpace/discover_quest/user_management_service/venv/lib/python3.8/site-packages/connexion/decorators/uri_parsing.py", line 149, in wrapper
    response = function(request)
  File "/home/minhmannh2001/Documents/CodeSpace/discover_quest/user_management_service/venv/lib/python3.8/site-packages/connexion/decorators/validation.py", line 196, in wrapper
    response = function(request)
  File "/home/minhmannh2001/Documents/CodeSpace/discover_quest/user_management_service/venv/lib/python3.8/site-packages/connexion/decorators/validation.py", line 399, in wrapper
    return function(request)
  File "/home/minhmannh2001/Documents/CodeSpace/discover_quest/user_management_service/venv/lib/python3.8/site-packages/connexion/decorators/parameter.py", line 120, in wrapper
    return function(**kwargs)
  File "/home/minhmannh2001/Documents/CodeSpace/discover_quest/user_management_service/app/controllers/user_controller.py", line 3, in create_user
    cleaned_data = validate(["email", "username", "password", "confirm_password"], user)
  File "/home/minhmannh2001/Documents/CodeSpace/discover_quest/user_management_service/app/controllers/user_controller.py", line 32, in validate
    for key, value in user_data.items():
AttributeError: 'str' object has no attribute 'items'
2023-08-24 23:15:26,175 ERROR: Exception on /v1/user [POST] [in /home/minhmannh2001/Documents/CodeSpace/discover_quest/user_management_service/venv/lib/python3.8/site-packages/flask/app.py:1744]
Traceback (most recent call last):
  File "/home/minhmannh2001/Documents/CodeSpace/discover_quest/user_management_service/venv/lib/python3.8/site-packages/flask/app.py", line 2529, in wsgi_app
    response = self.full_dispatch_request()
  File "/home/minhmannh2001/Documents/CodeSpace/discover_quest/user_management_service/venv/lib/python3.8/site-packages/flask/app.py", line 1825, in full_dispatch_request
    rv = self.handle_user_exception(e)
  File "/home/minhmannh2001/Documents/CodeSpace/discover_quest/user_management_service/venv/lib/python3.8/site-packages/flask/app.py", line 1823, in full_dispatch_request
    rv = self.dispatch_request()
  File "/home/minhmannh2001/Documents/CodeSpace/discover_quest/user_management_service/venv/lib/python3.8/site-packages/flask/app.py", line 1799, in dispatch_request
    return self.ensure_sync(self.view_functions[rule.endpoint])(**view_args)
  File "/home/minhmannh2001/Documents/CodeSpace/discover_quest/user_management_service/venv/lib/python3.8/site-packages/connexion/decorators/decorator.py", line 68, in wrapper
    response = function(request)
  File "/home/minhmannh2001/Documents/CodeSpace/discover_quest/user_management_service/venv/lib/python3.8/site-packages/connexion/security/security_handler_factory.py", line 388, in wrapper
    return function(request)
  File "/home/minhmannh2001/Documents/CodeSpace/discover_quest/user_management_service/venv/lib/python3.8/site-packages/connexion/decorators/uri_parsing.py", line 149, in wrapper
    response = function(request)
  File "/home/minhmannh2001/Documents/CodeSpace/discover_quest/user_management_service/venv/lib/python3.8/site-packages/connexion/decorators/validation.py", line 196, in wrapper
    response = function(request)
  File "/home/minhmannh2001/Documents/CodeSpace/discover_quest/user_management_service/venv/lib/python3.8/site-packages/connexion/decorators/validation.py", line 399, in wrapper
    return function(request)
  File "/home/minhmannh2001/Documents/CodeSpace/discover_quest/user_management_service/venv/lib/python3.8/site-packages/connexion/decorators/parameter.py", line 120, in wrapper
    return function(**kwargs)
  File "/home/minhmannh2001/Documents/CodeSpace/discover_quest/user_management_service/app/controllers/user_controller.py", line 3, in create_user
    cleaned_data = validate(["email", "username", "password", "confirm_password"], user)
  File "/home/minhmannh2001/Documents/CodeSpace/discover_quest/user_management_service/app/controllers/user_controller.py", line 32, in validate
    for key, value in user_data.items():
AttributeError: 'str' object has no attribute 'items'
2023-08-24 23:16:27,224 ERROR: Start logging API services at the error level. [in /home/minhmannh2001/Documents/CodeSpace/discover_quest/user_management_service/app/__init__.py:68]
2023-08-24 23:16:39,236 ERROR: Exception on /v1/user [POST] [in /home/minhmannh2001/Documents/CodeSpace/discover_quest/user_management_service/venv/lib/python3.8/site-packages/flask/app.py:1744]
Traceback (most recent call last):
  File "/home/minhmannh2001/Documents/CodeSpace/discover_quest/user_management_service/venv/lib/python3.8/site-packages/flask/app.py", line 2529, in wsgi_app
    response = self.full_dispatch_request()
  File "/home/minhmannh2001/Documents/CodeSpace/discover_quest/user_management_service/venv/lib/python3.8/site-packages/flask/app.py", line 1825, in full_dispatch_request
    rv = self.handle_user_exception(e)
  File "/home/minhmannh2001/Documents/CodeSpace/discover_quest/user_management_service/venv/lib/python3.8/site-packages/flask/app.py", line 1823, in full_dispatch_request
    rv = self.dispatch_request()
  File "/home/minhmannh2001/Documents/CodeSpace/discover_quest/user_management_service/venv/lib/python3.8/site-packages/flask/app.py", line 1799, in dispatch_request
    return self.ensure_sync(self.view_functions[rule.endpoint])(**view_args)
  File "/home/minhmannh2001/Documents/CodeSpace/discover_quest/user_management_service/venv/lib/python3.8/site-packages/connexion/decorators/decorator.py", line 68, in wrapper
    response = function(request)
  File "/home/minhmannh2001/Documents/CodeSpace/discover_quest/user_management_service/venv/lib/python3.8/site-packages/connexion/security/security_handler_factory.py", line 388, in wrapper
    return function(request)
  File "/home/minhmannh2001/Documents/CodeSpace/discover_quest/user_management_service/venv/lib/python3.8/site-packages/connexion/decorators/uri_parsing.py", line 149, in wrapper
    response = function(request)
  File "/home/minhmannh2001/Documents/CodeSpace/discover_quest/user_management_service/venv/lib/python3.8/site-packages/connexion/decorators/validation.py", line 196, in wrapper
    response = function(request)
  File "/home/minhmannh2001/Documents/CodeSpace/discover_quest/user_management_service/venv/lib/python3.8/site-packages/connexion/decorators/validation.py", line 399, in wrapper
    return function(request)
  File "/home/minhmannh2001/Documents/CodeSpace/discover_quest/user_management_service/venv/lib/python3.8/site-packages/connexion/decorators/parameter.py", line 120, in wrapper
    return function(**kwargs)
  File "/home/minhmannh2001/Documents/CodeSpace/discover_quest/user_management_service/venv/lib/python3.8/site-packages/flask_jwt_extended/view_decorators.py", line 174, in decorator
    return current_app.ensure_sync(fn)(*args, **kwargs)
  File "/home/minhmannh2001/Documents/CodeSpace/discover_quest/user_management_service/app/controllers/user_controller.py", line 7, in create_user
    cleaned_data = validate(["email", "username", "password", "confirm_password"], user)
  File "/home/minhmannh2001/Documents/CodeSpace/discover_quest/user_management_service/app/controllers/user_controller.py", line 36, in validate
    for key, value in user_data.items():
AttributeError: 'str' object has no attribute 'items'
2023-08-24 23:29:32,662 ERROR: Start logging API services at the error level. [in /home/minhmannh2001/Documents/CodeSpace/discover_quest/user_management_service/app/__init__.py:68]
2023-08-24 23:29:45,349 ERROR: Exception on /v1/user [POST] [in /home/minhmannh2001/Documents/CodeSpace/discover_quest/user_management_service/venv/lib/python3.8/site-packages/flask/app.py:1744]
Traceback (most recent call last):
  File "/home/minhmannh2001/Documents/CodeSpace/discover_quest/user_management_service/venv/lib/python3.8/site-packages/flask/app.py", line 2529, in wsgi_app
    response = self.full_dispatch_request()
  File "/home/minhmannh2001/Documents/CodeSpace/discover_quest/user_management_service/venv/lib/python3.8/site-packages/flask/app.py", line 1825, in full_dispatch_request
    rv = self.handle_user_exception(e)
  File "/home/minhmannh2001/Documents/CodeSpace/discover_quest/user_management_service/venv/lib/python3.8/site-packages/flask/app.py", line 1823, in full_dispatch_request
    rv = self.dispatch_request()
  File "/home/minhmannh2001/Documents/CodeSpace/discover_quest/user_management_service/venv/lib/python3.8/site-packages/flask/app.py", line 1799, in dispatch_request
    return self.ensure_sync(self.view_functions[rule.endpoint])(**view_args)
  File "/home/minhmannh2001/Documents/CodeSpace/discover_quest/user_management_service/venv/lib/python3.8/site-packages/connexion/decorators/decorator.py", line 68, in wrapper
    response = function(request)
  File "/home/minhmannh2001/Documents/CodeSpace/discover_quest/user_management_service/venv/lib/python3.8/site-packages/connexion/security/security_handler_factory.py", line 388, in wrapper
    return function(request)
  File "/home/minhmannh2001/Documents/CodeSpace/discover_quest/user_management_service/venv/lib/python3.8/site-packages/connexion/decorators/uri_parsing.py", line 149, in wrapper
    response = function(request)
  File "/home/minhmannh2001/Documents/CodeSpace/discover_quest/user_management_service/venv/lib/python3.8/site-packages/connexion/decorators/validation.py", line 196, in wrapper
    response = function(request)
  File "/home/minhmannh2001/Documents/CodeSpace/discover_quest/user_management_service/venv/lib/python3.8/site-packages/connexion/decorators/validation.py", line 399, in wrapper
    return function(request)
  File "/home/minhmannh2001/Documents/CodeSpace/discover_quest/user_management_service/venv/lib/python3.8/site-packages/connexion/decorators/parameter.py", line 120, in wrapper
    return function(**kwargs)
  File "/home/minhmannh2001/Documents/CodeSpace/discover_quest/user_management_service/venv/lib/python3.8/site-packages/flask_jwt_extended/view_decorators.py", line 174, in decorator
    return current_app.ensure_sync(fn)(*args, **kwargs)
TypeError: create_user() missing 1 required positional argument: 'user_input'
2023-08-24 23:30:08,226 ERROR: Start logging API services at the error level. [in /home/minhmannh2001/Documents/CodeSpace/discover_quest/user_management_service/app/__init__.py:68]
2023-08-24 23:31:52,489 ERROR: Exception on /v1/user [POST] [in /home/minhmannh2001/Documents/CodeSpace/discover_quest/user_management_service/venv/lib/python3.8/site-packages/flask/app.py:1744]
Traceback (most recent call last):
  File "/home/minhmannh2001/Documents/CodeSpace/discover_quest/user_management_service/venv/lib/python3.8/site-packages/flask/app.py", line 2529, in wsgi_app
    response = self.full_dispatch_request()
  File "/home/minhmannh2001/Documents/CodeSpace/discover_quest/user_management_service/venv/lib/python3.8/site-packages/flask/app.py", line 1825, in full_dispatch_request
    rv = self.handle_user_exception(e)
  File "/home/minhmannh2001/Documents/CodeSpace/discover_quest/user_management_service/venv/lib/python3.8/site-packages/flask/app.py", line 1823, in full_dispatch_request
    rv = self.dispatch_request()
  File "/home/minhmannh2001/Documents/CodeSpace/discover_quest/user_management_service/venv/lib/python3.8/site-packages/flask/app.py", line 1799, in dispatch_request
    return self.ensure_sync(self.view_functions[rule.endpoint])(**view_args)
  File "/home/minhmannh2001/Documents/CodeSpace/discover_quest/user_management_service/venv/lib/python3.8/site-packages/connexion/decorators/decorator.py", line 68, in wrapper
    response = function(request)
  File "/home/minhmannh2001/Documents/CodeSpace/discover_quest/user_management_service/venv/lib/python3.8/site-packages/connexion/security/security_handler_factory.py", line 388, in wrapper
    return function(request)
  File "/home/minhmannh2001/Documents/CodeSpace/discover_quest/user_management_service/venv/lib/python3.8/site-packages/connexion/decorators/uri_parsing.py", line 149, in wrapper
    response = function(request)
  File "/home/minhmannh2001/Documents/CodeSpace/discover_quest/user_management_service/venv/lib/python3.8/site-packages/connexion/decorators/validation.py", line 196, in wrapper
    response = function(request)
  File "/home/minhmannh2001/Documents/CodeSpace/discover_quest/user_management_service/venv/lib/python3.8/site-packages/connexion/decorators/validation.py", line 399, in wrapper
    return function(request)
  File "/home/minhmannh2001/Documents/CodeSpace/discover_quest/user_management_service/venv/lib/python3.8/site-packages/connexion/decorators/parameter.py", line 120, in wrapper
    return function(**kwargs)
  File "/home/minhmannh2001/Documents/CodeSpace/discover_quest/user_management_service/venv/lib/python3.8/site-packages/flask_jwt_extended/view_decorators.py", line 174, in decorator
    return current_app.ensure_sync(fn)(*args, **kwargs)
  File "/home/minhmannh2001/Documents/CodeSpace/discover_quest/user_management_service/app/controllers/user_controller.py", line 7, in create_user
    cleaned_data = validate(["email", "username", "password", "confirm_password"], user)
  File "/home/minhmannh2001/Documents/CodeSpace/discover_quest/user_management_service/app/controllers/user_controller.py", line 36, in validate
    for key, value in user_data.items():
AttributeError: 'str' object has no attribute 'items'
2023-08-24 23:32:26,921 ERROR: Start logging API services at the error level. [in /home/minhmannh2001/Documents/CodeSpace/discover_quest/user_management_service/app/__init__.py:68]
2023-08-24 23:58:48,379 ERROR: Start logging API services at the error level. [in /home/minhmannh2001/Documents/CodeSpace/discover_quest/user_management_service/app/__init__.py:68]
2023-08-24 23:59:28,347 ERROR: Exception on /v1/user [POST] [in /home/minhmannh2001/Documents/CodeSpace/discover_quest/user_management_service/venv/lib/python3.8/site-packages/flask/app.py:1744]
Traceback (most recent call last):
  File "/home/minhmannh2001/Documents/CodeSpace/discover_quest/user_management_service/venv/lib/python3.8/site-packages/flask/app.py", line 2529, in wsgi_app
    response = self.full_dispatch_request()
  File "/home/minhmannh2001/Documents/CodeSpace/discover_quest/user_management_service/venv/lib/python3.8/site-packages/flask/app.py", line 1825, in full_dispatch_request
    rv = self.handle_user_exception(e)
  File "/home/minhmannh2001/Documents/CodeSpace/discover_quest/user_management_service/venv/lib/python3.8/site-packages/flask/app.py", line 1823, in full_dispatch_request
    rv = self.dispatch_request()
  File "/home/minhmannh2001/Documents/CodeSpace/discover_quest/user_management_service/venv/lib/python3.8/site-packages/flask/app.py", line 1799, in dispatch_request
    return self.ensure_sync(self.view_functions[rule.endpoint])(**view_args)
  File "/home/minhmannh2001/Documents/CodeSpace/discover_quest/user_management_service/venv/lib/python3.8/site-packages/connexion/decorators/decorator.py", line 68, in wrapper
    response = function(request)
  File "/home/minhmannh2001/Documents/CodeSpace/discover_quest/user_management_service/venv/lib/python3.8/site-packages/connexion/security/security_handler_factory.py", line 388, in wrapper
    return function(request)
  File "/home/minhmannh2001/Documents/CodeSpace/discover_quest/user_management_service/venv/lib/python3.8/site-packages/connexion/decorators/uri_parsing.py", line 149, in wrapper
    response = function(request)
  File "/home/minhmannh2001/Documents/CodeSpace/discover_quest/user_management_service/venv/lib/python3.8/site-packages/connexion/decorators/validation.py", line 196, in wrapper
    response = function(request)
  File "/home/minhmannh2001/Documents/CodeSpace/discover_quest/user_management_service/venv/lib/python3.8/site-packages/connexion/decorators/validation.py", line 399, in wrapper
    return function(request)
  File "/home/minhmannh2001/Documents/CodeSpace/discover_quest/user_management_service/venv/lib/python3.8/site-packages/connexion/decorators/parameter.py", line 120, in wrapper
    return function(**kwargs)
  File "/home/minhmannh2001/Documents/CodeSpace/discover_quest/user_management_service/venv/lib/python3.8/site-packages/flask_jwt_extended/view_decorators.py", line 174, in decorator
    return current_app.ensure_sync(fn)(*args, **kwargs)
  File "/home/minhmannh2001/Documents/CodeSpace/discover_quest/user_management_service/app/controllers/user_controller.py", line 11, in create_user
    user = User.query.filter_by(or_(User.username == user_input["username"], User.email == user_input["email"]))
TypeError: filter_by() takes 1 positional argument but 2 were given
2023-08-24 23:59:37,563 ERROR: Exception on /v1/user [POST] [in /home/minhmannh2001/Documents/CodeSpace/discover_quest/user_management_service/venv/lib/python3.8/site-packages/flask/app.py:1744]
Traceback (most recent call last):
  File "/home/minhmannh2001/Documents/CodeSpace/discover_quest/user_management_service/venv/lib/python3.8/site-packages/flask/app.py", line 2529, in wsgi_app
    response = self.full_dispatch_request()
  File "/home/minhmannh2001/Documents/CodeSpace/discover_quest/user_management_service/venv/lib/python3.8/site-packages/flask/app.py", line 1825, in full_dispatch_request
    rv = self.handle_user_exception(e)
  File "/home/minhmannh2001/Documents/CodeSpace/discover_quest/user_management_service/venv/lib/python3.8/site-packages/flask/app.py", line 1823, in full_dispatch_request
    rv = self.dispatch_request()
  File "/home/minhmannh2001/Documents/CodeSpace/discover_quest/user_management_service/venv/lib/python3.8/site-packages/flask/app.py", line 1799, in dispatch_request
    return self.ensure_sync(self.view_functions[rule.endpoint])(**view_args)
  File "/home/minhmannh2001/Documents/CodeSpace/discover_quest/user_management_service/venv/lib/python3.8/site-packages/connexion/decorators/decorator.py", line 68, in wrapper
    response = function(request)
  File "/home/minhmannh2001/Documents/CodeSpace/discover_quest/user_management_service/venv/lib/python3.8/site-packages/connexion/security/security_handler_factory.py", line 388, in wrapper
    return function(request)
  File "/home/minhmannh2001/Documents/CodeSpace/discover_quest/user_management_service/venv/lib/python3.8/site-packages/connexion/decorators/uri_parsing.py", line 149, in wrapper
    response = function(request)
  File "/home/minhmannh2001/Documents/CodeSpace/discover_quest/user_management_service/venv/lib/python3.8/site-packages/connexion/decorators/validation.py", line 196, in wrapper
    response = function(request)
  File "/home/minhmannh2001/Documents/CodeSpace/discover_quest/user_management_service/venv/lib/python3.8/site-packages/connexion/decorators/validation.py", line 399, in wrapper
    return function(request)
  File "/home/minhmannh2001/Documents/CodeSpace/discover_quest/user_management_service/venv/lib/python3.8/site-packages/connexion/decorators/parameter.py", line 120, in wrapper
    return function(**kwargs)
  File "/home/minhmannh2001/Documents/CodeSpace/discover_quest/user_management_service/venv/lib/python3.8/site-packages/flask_jwt_extended/view_decorators.py", line 174, in decorator
    return current_app.ensure_sync(fn)(*args, **kwargs)
  File "/home/minhmannh2001/Documents/CodeSpace/discover_quest/user_management_service/app/controllers/user_controller.py", line 11, in create_user
    user = User.query.filter_by(or_(User.username == user_input["username"], User.email == user_input["email"]))
TypeError: filter_by() takes 1 positional argument but 2 were given
2023-08-25 00:00:19,087 ERROR: Start logging API services at the error level. [in /home/minhmannh2001/Documents/CodeSpace/discover_quest/user_management_service/app/__init__.py:68]
2023-08-25 00:01:39,540 ERROR: Start logging API services at the error level. [in /home/minhmannh2001/Documents/CodeSpace/discover_quest/user_management_service/app/__init__.py:68]
2023-08-25 00:04:39,656 ERROR: Start logging API services at the error level. [in /home/minhmannh2001/Documents/CodeSpace/discover_quest/user_management_service/app/__init__.py:68]
2023-08-25 00:20:35,053 ERROR: Start logging API services at the error level. [in /home/minhmannh2001/Documents/CodeSpace/discover_quest/user_management_service/app/__init__.py:68]
2023-08-25 00:30:19,022 ERROR: Start logging API services at the error level. [in /home/minhmannh2001/Documents/CodeSpace/discover_quest/user_management_service/app/__init__.py:68]
2023-08-25 00:30:22,924 ERROR: Exception on /v1/user [POST] [in /home/minhmannh2001/Documents/CodeSpace/discover_quest/user_management_service/venv/lib/python3.8/site-packages/flask/app.py:1744]
Traceback (most recent call last):
  File "/home/minhmannh2001/Documents/CodeSpace/discover_quest/user_management_service/venv/lib/python3.8/site-packages/flask/app.py", line 2529, in wsgi_app
    response = self.full_dispatch_request()
  File "/home/minhmannh2001/Documents/CodeSpace/discover_quest/user_management_service/venv/lib/python3.8/site-packages/flask/app.py", line 1825, in full_dispatch_request
    rv = self.handle_user_exception(e)
  File "/home/minhmannh2001/Documents/CodeSpace/discover_quest/user_management_service/venv/lib/python3.8/site-packages/flask/app.py", line 1823, in full_dispatch_request
    rv = self.dispatch_request()
  File "/home/minhmannh2001/Documents/CodeSpace/discover_quest/user_management_service/venv/lib/python3.8/site-packages/flask/app.py", line 1799, in dispatch_request
    return self.ensure_sync(self.view_functions[rule.endpoint])(**view_args)
  File "/home/minhmannh2001/Documents/CodeSpace/discover_quest/user_management_service/venv/lib/python3.8/site-packages/connexion/decorators/decorator.py", line 69, in wrapper
    return self.api.get_response(response, self.mimetype, request)
  File "/home/minhmannh2001/Documents/CodeSpace/discover_quest/user_management_service/venv/lib/python3.8/site-packages/connexion/apis/flask_api.py", line 150, in get_response
    return cls._get_response(response, mimetype=mimetype, extra_context={"url": flask.request.url})
  File "/home/minhmannh2001/Documents/CodeSpace/discover_quest/user_management_service/venv/lib/python3.8/site-packages/connexion/apis/abstract.py", line 290, in _get_response
    framework_response = cls._response_from_handler(response, mimetype, extra_context)
  File "/home/minhmannh2001/Documents/CodeSpace/discover_quest/user_management_service/venv/lib/python3.8/site-packages/connexion/apis/abstract.py", line 331, in _response_from_handler
    return cls._build_response(mimetype=mimetype, data=data, status_code=status_code, extra_context=extra_context)
  File "/home/minhmannh2001/Documents/CodeSpace/discover_quest/user_management_service/venv/lib/python3.8/site-packages/connexion/apis/flask_api.py", line 188, in _build_response
    data, status_code, serialized_mimetype = cls._prepare_body_and_status_code(data=data, mimetype=mimetype, status_code=status_code, extra_context=extra_context)
  File "/home/minhmannh2001/Documents/CodeSpace/discover_quest/user_management_service/venv/lib/python3.8/site-packages/connexion/apis/abstract.py", line 417, in _prepare_body_and_status_code
    body, mimetype = cls._serialize_data(data, mimetype)
  File "/home/minhmannh2001/Documents/CodeSpace/discover_quest/user_management_service/venv/lib/python3.8/site-packages/connexion/apis/flask_api.py", line 205, in _serialize_data
    body = cls.jsonifier.dumps(data)
  File "/home/minhmannh2001/Documents/CodeSpace/discover_quest/user_management_service/venv/lib/python3.8/site-packages/connexion/jsonifier.py", line 57, in dumps
    return self.json.dumps(data, **kwargs) + '\n'
  File "/home/minhmannh2001/Documents/CodeSpace/discover_quest/user_management_service/venv/lib/python3.8/site-packages/flask/json/__init__.py", line 124, in dumps
    return app.json.dumps(obj, **kwargs)
  File "/home/minhmannh2001/Documents/CodeSpace/discover_quest/user_management_service/venv/lib/python3.8/site-packages/flask/json/provider.py", line 230, in dumps
    return json.dumps(obj, **kwargs)
  File "/usr/lib/python3.8/json/__init__.py", line 234, in dumps
    return cls(
  File "/usr/lib/python3.8/json/encoder.py", line 201, in encode
    chunks = list(chunks)
  File "/usr/lib/python3.8/json/encoder.py", line 438, in _iterencode
    o = _default(o)
  File "/home/minhmannh2001/Documents/CodeSpace/discover_quest/user_management_service/venv/lib/python3.8/site-packages/connexion/apps/flask_app.py", line 170, in default
    return json.JSONEncoder.default(self, o)
  File "/home/minhmannh2001/Documents/CodeSpace/discover_quest/user_management_service/venv/lib/python3.8/site-packages/flask/json/__init__.py", line 55, in default
    return _default(o)
  File "/home/minhmannh2001/Documents/CodeSpace/discover_quest/user_management_service/venv/lib/python3.8/site-packages/flask/json/provider.py", line 122, in _default
    raise TypeError(f"Object of type {type(o).__name__} is not JSON serializable")
TypeError: Object of type Conflict is not JSON serializable
2023-08-25 00:33:00,566 ERROR: Start logging API services at the error level. [in /home/minhmannh2001/Documents/CodeSpace/discover_quest/user_management_service/app/__init__.py:68]
2023-08-25 00:33:31,322 ERROR: Start logging API services at the error level. [in /home/minhmannh2001/Documents/CodeSpace/discover_quest/user_management_service/app/__init__.py:68]
2023-08-25 00:33:47,227 ERROR: Start logging API services at the error level. [in /home/minhmannh2001/Documents/CodeSpace/discover_quest/user_management_service/app/__init__.py:68]
2023-08-25 00:39:30,869 ERROR: Start logging API services at the error level. [in /home/minhmannh2001/Documents/CodeSpace/discover_quest/user_management_service/app/__init__.py:68]
2023-08-25 00:39:50,360 ERROR: Start logging API services at the error level. [in /home/minhmannh2001/Documents/CodeSpace/discover_quest/user_management_service/app/__init__.py:68]
2023-08-25 00:39:57,088 ERROR: Exception on /v1/user [POST] [in /home/minhmannh2001/Documents/CodeSpace/discover_quest/user_management_service/venv/lib/python3.8/site-packages/flask/app.py:1744]
Traceback (most recent call last):
  File "/home/minhmannh2001/Documents/CodeSpace/discover_quest/user_management_service/venv/lib/python3.8/site-packages/flask/app.py", line 2529, in wsgi_app
    response = self.full_dispatch_request()
  File "/home/minhmannh2001/Documents/CodeSpace/discover_quest/user_management_service/venv/lib/python3.8/site-packages/flask/app.py", line 1825, in full_dispatch_request
    rv = self.handle_user_exception(e)
  File "/home/minhmannh2001/Documents/CodeSpace/discover_quest/user_management_service/venv/lib/python3.8/site-packages/flask/app.py", line 1823, in full_dispatch_request
    rv = self.dispatch_request()
  File "/home/minhmannh2001/Documents/CodeSpace/discover_quest/user_management_service/venv/lib/python3.8/site-packages/flask/app.py", line 1799, in dispatch_request
    return self.ensure_sync(self.view_functions[rule.endpoint])(**view_args)
  File "/home/minhmannh2001/Documents/CodeSpace/discover_quest/user_management_service/venv/lib/python3.8/site-packages/connexion/decorators/decorator.py", line 68, in wrapper
    response = function(request)
  File "/home/minhmannh2001/Documents/CodeSpace/discover_quest/user_management_service/venv/lib/python3.8/site-packages/connexion/security/security_handler_factory.py", line 388, in wrapper
    return function(request)
  File "/home/minhmannh2001/Documents/CodeSpace/discover_quest/user_management_service/venv/lib/python3.8/site-packages/connexion/decorators/uri_parsing.py", line 149, in wrapper
    response = function(request)
  File "/home/minhmannh2001/Documents/CodeSpace/discover_quest/user_management_service/venv/lib/python3.8/site-packages/connexion/decorators/validation.py", line 196, in wrapper
    response = function(request)
  File "/home/minhmannh2001/Documents/CodeSpace/discover_quest/user_management_service/venv/lib/python3.8/site-packages/connexion/decorators/validation.py", line 399, in wrapper
    return function(request)
  File "/home/minhmannh2001/Documents/CodeSpace/discover_quest/user_management_service/venv/lib/python3.8/site-packages/connexion/decorators/parameter.py", line 120, in wrapper
    return function(**kwargs)
  File "/home/minhmannh2001/Documents/CodeSpace/discover_quest/user_management_service/venv/lib/python3.8/site-packages/flask_jwt_extended/view_decorators.py", line 174, in decorator
    return current_app.ensure_sync(fn)(*args, **kwargs)
  File "/home/minhmannh2001/Documents/CodeSpace/discover_quest/user_management_service/app/controllers/user_controller.py", line 26, in create_user
    postgres_connection.db.add(new_user)
  File "/home/minhmannh2001/Documents/CodeSpace/discover_quest/user_management_service/venv/lib/python3.8/site-packages/flask_sqlalchemy/extension.py", line 1008, in __getattr__
    raise AttributeError(name)
AttributeError: add
2023-08-25 00:41:18,616 ERROR: Start logging API services at the error level. [in /home/minhmannh2001/Documents/CodeSpace/discover_quest/user_management_service/app/__init__.py:68]
2023-08-26 10:08:19,709 ERROR: Start logging API services at the error level. [in /home/minhmannh2001/Documents/CodeSpace/discover_quest/user_management_service/app/__init__.py:68]
2023-08-26 11:01:58,601 ERROR: Start logging API services at the error level. [in /home/minhmannh2001/Documents/CodeSpace/discover_quest/user_management_service/app/__init__.py:78]
2023-08-26 11:03:01,029 ERROR: Start logging API services at the error level. [in /home/minhmannh2001/Documents/CodeSpace/discover_quest/user_management_service/app/__init__.py:78]
2023-08-26 11:03:20,069 ERROR: Start logging API services at the error level. [in /home/minhmannh2001/Documents/CodeSpace/discover_quest/user_management_service/app/__init__.py:78]
2023-08-26 11:10:32,769 ERROR: Start logging API services at the error level. [in /home/minhmannh2001/Documents/CodeSpace/discover_quest/user_management_service/app/__init__.py:78]
2023-08-26 11:13:35,365 ERROR: Exception on /v1/user [POST] [in /home/minhmannh2001/Documents/CodeSpace/discover_quest/user_management_service/venv/lib/python3.8/site-packages/flask/app.py:1744]
Traceback (most recent call last):
  File "/home/minhmannh2001/Documents/CodeSpace/discover_quest/user_management_service/venv/lib/python3.8/site-packages/flask/app.py", line 2529, in wsgi_app
    response = self.full_dispatch_request()
  File "/home/minhmannh2001/Documents/CodeSpace/discover_quest/user_management_service/venv/lib/python3.8/site-packages/flask/app.py", line 1825, in full_dispatch_request
    rv = self.handle_user_exception(e)
  File "/home/minhmannh2001/Documents/CodeSpace/discover_quest/user_management_service/venv/lib/python3.8/site-packages/flask/app.py", line 1823, in full_dispatch_request
    rv = self.dispatch_request()
  File "/home/minhmannh2001/Documents/CodeSpace/discover_quest/user_management_service/venv/lib/python3.8/site-packages/flask/app.py", line 1799, in dispatch_request
    return self.ensure_sync(self.view_functions[rule.endpoint])(**view_args)
  File "/home/minhmannh2001/Documents/CodeSpace/discover_quest/user_management_service/venv/lib/python3.8/site-packages/connexion/decorators/decorator.py", line 68, in wrapper
    response = function(request)
  File "/home/minhmannh2001/Documents/CodeSpace/discover_quest/user_management_service/venv/lib/python3.8/site-packages/connexion/security/security_handler_factory.py", line 380, in wrapper
    cls._raise_most_specific(errors)
  File "/home/minhmannh2001/Documents/CodeSpace/discover_quest/user_management_service/venv/lib/python3.8/site-packages/connexion/security/security_handler_factory.py", line 421, in _raise_most_specific
    raise status_to_exc[lowest_status_code]
  File "/home/minhmannh2001/Documents/CodeSpace/discover_quest/user_management_service/venv/lib/python3.8/site-packages/connexion/security/security_handler_factory.py", line 372, in wrapper
    token_info = func(request)
  File "/home/minhmannh2001/Documents/CodeSpace/discover_quest/user_management_service/venv/lib/python3.8/site-packages/connexion/security/security_handler_factory.py", line 255, in wrapper
    return check_api_key_func(request, api_key)
  File "/home/minhmannh2001/Documents/CodeSpace/discover_quest/user_management_service/venv/lib/python3.8/site-packages/connexion/security/security_handler_factory.py", line 322, in wrapper
    token_info = func(*args, **kwargs)
  File "/home/minhmannh2001/Documents/CodeSpace/discover_quest/user_management_service/helpers/utils.py", line 61, in api_info_func
    raise Exception("Permission denied")
Exception: Permission denied
2023-08-26 11:15:55,525 ERROR: Start logging API services at the error level. [in /home/minhmannh2001/Documents/CodeSpace/discover_quest/user_management_service/app/__init__.py:78]
2023-08-26 11:32:55,315 ERROR: Start logging API services at the error level. [in /home/minhmannh2001/Documents/CodeSpace/discover_quest/user_management_service/app/__init__.py:78]
2023-08-26 11:35:21,530 ERROR: Start logging API services at the error level. [in /home/minhmannh2001/Documents/CodeSpace/discover_quest/user_management_service/app/__init__.py:78]
2023-08-26 11:37:23,105 ERROR: Start logging API services at the error level. [in /home/minhmannh2001/Documents/CodeSpace/discover_quest/user_management_service/app/__init__.py:78]
2023-08-26 11:37:28,206 ERROR: Exception on /v1/user [POST] [in /home/minhmannh2001/Documents/CodeSpace/discover_quest/user_management_service/venv/lib/python3.8/site-packages/flask/app.py:1744]
Traceback (most recent call last):
  File "/home/minhmannh2001/Documents/CodeSpace/discover_quest/user_management_service/venv/lib/python3.8/site-packages/flask/app.py", line 2529, in wsgi_app
    response = self.full_dispatch_request()
  File "/home/minhmannh2001/Documents/CodeSpace/discover_quest/user_management_service/venv/lib/python3.8/site-packages/flask/app.py", line 1825, in full_dispatch_request
    rv = self.handle_user_exception(e)
  File "/home/minhmannh2001/Documents/CodeSpace/discover_quest/user_management_service/venv/lib/python3.8/site-packages/flask/app.py", line 1823, in full_dispatch_request
    rv = self.dispatch_request()
  File "/home/minhmannh2001/Documents/CodeSpace/discover_quest/user_management_service/venv/lib/python3.8/site-packages/flask/app.py", line 1799, in dispatch_request
    return self.ensure_sync(self.view_functions[rule.endpoint])(**view_args)
  File "/home/minhmannh2001/Documents/CodeSpace/discover_quest/user_management_service/venv/lib/python3.8/site-packages/connexion/decorators/decorator.py", line 68, in wrapper
    response = function(request)
  File "/home/minhmannh2001/Documents/CodeSpace/discover_quest/user_management_service/venv/lib/python3.8/site-packages/connexion/security/security_handler_factory.py", line 380, in wrapper
    cls._raise_most_specific(errors)
  File "/home/minhmannh2001/Documents/CodeSpace/discover_quest/user_management_service/venv/lib/python3.8/site-packages/connexion/security/security_handler_factory.py", line 421, in _raise_most_specific
    raise status_to_exc[lowest_status_code]
  File "/home/minhmannh2001/Documents/CodeSpace/discover_quest/user_management_service/venv/lib/python3.8/site-packages/connexion/security/security_handler_factory.py", line 372, in wrapper
    token_info = func(request)
  File "/home/minhmannh2001/Documents/CodeSpace/discover_quest/user_management_service/venv/lib/python3.8/site-packages/connexion/security/security_handler_factory.py", line 255, in wrapper
    return check_api_key_func(request, api_key)
  File "/home/minhmannh2001/Documents/CodeSpace/discover_quest/user_management_service/venv/lib/python3.8/site-packages/connexion/security/security_handler_factory.py", line 322, in wrapper
    token_info = func(*args, **kwargs)
  File "/home/minhmannh2001/Documents/CodeSpace/discover_quest/user_management_service/helpers/utils.py", line 61, in api_info_func
    raise Exception("Permission denied")
Exception: Permission denied
2023-08-26 11:38:59,743 ERROR: Exception on /v1/user [POST] [in /home/minhmannh2001/Documents/CodeSpace/discover_quest/user_management_service/venv/lib/python3.8/site-packages/flask/app.py:1744]
Traceback (most recent call last):
  File "/home/minhmannh2001/Documents/CodeSpace/discover_quest/user_management_service/venv/lib/python3.8/site-packages/flask/app.py", line 2529, in wsgi_app
    response = self.full_dispatch_request()
  File "/home/minhmannh2001/Documents/CodeSpace/discover_quest/user_management_service/venv/lib/python3.8/site-packages/flask/app.py", line 1825, in full_dispatch_request
    rv = self.handle_user_exception(e)
  File "/home/minhmannh2001/Documents/CodeSpace/discover_quest/user_management_service/venv/lib/python3.8/site-packages/flask/app.py", line 1823, in full_dispatch_request
    rv = self.dispatch_request()
  File "/home/minhmannh2001/Documents/CodeSpace/discover_quest/user_management_service/venv/lib/python3.8/site-packages/flask/app.py", line 1799, in dispatch_request
    return self.ensure_sync(self.view_functions[rule.endpoint])(**view_args)
  File "/home/minhmannh2001/Documents/CodeSpace/discover_quest/user_management_service/venv/lib/python3.8/site-packages/connexion/decorators/decorator.py", line 68, in wrapper
    response = function(request)
  File "/home/minhmannh2001/Documents/CodeSpace/discover_quest/user_management_service/venv/lib/python3.8/site-packages/connexion/security/security_handler_factory.py", line 380, in wrapper
    cls._raise_most_specific(errors)
  File "/home/minhmannh2001/Documents/CodeSpace/discover_quest/user_management_service/venv/lib/python3.8/site-packages/connexion/security/security_handler_factory.py", line 421, in _raise_most_specific
    raise status_to_exc[lowest_status_code]
  File "/home/minhmannh2001/Documents/CodeSpace/discover_quest/user_management_service/venv/lib/python3.8/site-packages/connexion/security/security_handler_factory.py", line 372, in wrapper
    token_info = func(request)
  File "/home/minhmannh2001/Documents/CodeSpace/discover_quest/user_management_service/venv/lib/python3.8/site-packages/connexion/security/security_handler_factory.py", line 255, in wrapper
    return check_api_key_func(request, api_key)
  File "/home/minhmannh2001/Documents/CodeSpace/discover_quest/user_management_service/venv/lib/python3.8/site-packages/connexion/security/security_handler_factory.py", line 322, in wrapper
    token_info = func(*args, **kwargs)
  File "/home/minhmannh2001/Documents/CodeSpace/discover_quest/user_management_service/helpers/utils.py", line 61, in api_info_func
    raise Exception("Permission denied")
Exception: Permission denied
2023-08-26 11:39:29,091 ERROR: Start logging API services at the error level. [in /home/minhmannh2001/Documents/CodeSpace/discover_quest/user_management_service/app/__init__.py:78]
2023-08-26 11:41:25,141 ERROR: Start logging API services at the error level. [in /home/minhmannh2001/Documents/CodeSpace/discover_quest/user_management_service/app/__init__.py:78]
2023-08-26 11:42:25,366 ERROR: Start logging API services at the error level. [in /home/minhmannh2001/Documents/CodeSpace/discover_quest/user_management_service/app/__init__.py:78]
2023-08-26 11:44:30,603 ERROR: Start logging API services at the error level. [in /home/minhmannh2001/Documents/CodeSpace/discover_quest/user_management_service/app/__init__.py:78]
2023-08-26 11:44:42,425 ERROR: Start logging API services at the error level. [in /home/minhmannh2001/Documents/CodeSpace/discover_quest/user_management_service/app/__init__.py:78]
2023-08-26 11:44:46,588 ERROR: Start logging API services at the error level. [in /home/minhmannh2001/Documents/CodeSpace/discover_quest/user_management_service/app/__init__.py:78]
2023-08-26 11:48:06,004 ERROR: Start logging API services at the error level. [in /home/minhmannh2001/Documents/CodeSpace/discover_quest/user_management_service/app/__init__.py:78]
2023-08-26 11:49:36,016 ERROR: Start logging API services at the error level. [in /home/minhmannh2001/Documents/CodeSpace/discover_quest/user_management_service/app/__init__.py:78]
2023-08-26 11:50:47,308 ERROR: Start logging API services at the error level. [in /home/minhmannh2001/Documents/CodeSpace/discover_quest/user_management_service/app/__init__.py:78]
2023-08-26 11:55:09,585 ERROR: Start logging API services at the error level. [in /home/minhmannh2001/Documents/CodeSpace/discover_quest/user_management_service/app/__init__.py:78]
2023-08-26 11:56:29,010 ERROR: Start logging API services at the error level. [in /home/minhmannh2001/Documents/CodeSpace/discover_quest/user_management_service/app/__init__.py:78]
2023-08-26 11:56:57,692 ERROR: Start logging API services at the error level. [in /home/minhmannh2001/Documents/CodeSpace/discover_quest/user_management_service/app/__init__.py:78]
2023-08-26 12:05:59,386 ERROR: Start logging API services at the error level. [in /home/minhmannh2001/Documents/CodeSpace/discover_quest/user_management_service/app/__init__.py:78]
2023-08-26 12:07:18,795 ERROR: Start logging API services at the error level. [in /home/minhmannh2001/Documents/CodeSpace/discover_quest/user_management_service/app/__init__.py:78]
2023-08-26 12:07:37,305 ERROR: Start logging API services at the error level. [in /home/minhmannh2001/Documents/CodeSpace/discover_quest/user_management_service/app/__init__.py:78]
2023-08-26 12:35:49,039 ERROR: Start logging API services at the error level. [in /home/minhmannh2001/Documents/CodeSpace/discover_quest/user_management_service/app/__init__.py:68]
2023-08-26 12:37:52,497 ERROR: Start logging API services at the error level. [in /home/minhmannh2001/Documents/CodeSpace/discover_quest/user_management_service/app/__init__.py:68]
2023-08-26 23:14:13,117 ERROR: Start logging API services at the error level. [in /home/minhmannh2001/Documents/CodeSpace/discover_quest/user_management_service/app/__init__.py:67]
2023-08-31 01:55:34,553 ERROR: Start logging API services at the error level. [in /home/minhmannh2001/Documents/CodeSpace/discover_quest/user_management_service/app/__init__.py:67]
2023-09-02 01:57:24,353 ERROR: Start logging API services at the error level. [in /home/minhmannh2001/Documents/CodeSpace/discover_quest/user_management_service/app/__init__.py:67]
2023-09-02 02:17:44,599 ERROR: Start logging API services at the error level. [in /home/minhmannh2001/Documents/CodeSpace/discover_quest/user_management_service/app/__init__.py:67]
2023-09-02 02:23:36,442 ERROR: Start logging API services at the error level. [in /home/minhmannh2001/Documents/CodeSpace/discover_quest/user_management_service/app/__init__.py:67]
2023-09-02 02:30:30,007 ERROR: Start logging API services at the error level. [in /home/minhmannh2001/Documents/CodeSpace/discover_quest/user_management_service/app/__init__.py:67]
2023-09-02 02:36:35,782 ERROR: Start logging API services at the error level. [in /home/minhmannh2001/Documents/CodeSpace/discover_quest/user_management_service/app/__init__.py:67]
2023-09-02 02:37:07,218 ERROR: Exception on /v1/users/john.doe@example.com [GET] [in /home/minhmannh2001/Documents/CodeSpace/discover_quest/user_management_service/venv/lib/python3.8/site-packages/flask/app.py:1744]
Traceback (most recent call last):
  File "/home/minhmannh2001/Documents/CodeSpace/discover_quest/user_management_service/venv/lib/python3.8/site-packages/sqlalchemy/engine/base.py", line 1965, in _exec_single_context
    self.dialect.do_execute(
  File "/home/minhmannh2001/Documents/CodeSpace/discover_quest/user_management_service/venv/lib/python3.8/site-packages/sqlalchemy/engine/default.py", line 921, in do_execute
    cursor.execute(statement, parameters)
psycopg2.errors.InvalidTextRepresentation: invalid input syntax for type integer: "john.doe@example.com"
LINE 3: WHERE users.user_id = 'john.doe@example.com' OR users.userna...
                              ^


The above exception was the direct cause of the following exception:

Traceback (most recent call last):
  File "/home/minhmannh2001/Documents/CodeSpace/discover_quest/user_management_service/venv/lib/python3.8/site-packages/flask/app.py", line 2529, in wsgi_app
    response = self.full_dispatch_request()
  File "/home/minhmannh2001/Documents/CodeSpace/discover_quest/user_management_service/venv/lib/python3.8/site-packages/flask/app.py", line 1825, in full_dispatch_request
    rv = self.handle_user_exception(e)
  File "/home/minhmannh2001/Documents/CodeSpace/discover_quest/user_management_service/venv/lib/python3.8/site-packages/flask/app.py", line 1823, in full_dispatch_request
    rv = self.dispatch_request()
  File "/home/minhmannh2001/Documents/CodeSpace/discover_quest/user_management_service/venv/lib/python3.8/site-packages/flask/app.py", line 1799, in dispatch_request
    return self.ensure_sync(self.view_functions[rule.endpoint])(**view_args)
  File "/home/minhmannh2001/Documents/CodeSpace/discover_quest/user_management_service/venv/lib/python3.8/site-packages/connexion/decorators/decorator.py", line 68, in wrapper
    response = function(request)
  File "/home/minhmannh2001/Documents/CodeSpace/discover_quest/user_management_service/venv/lib/python3.8/site-packages/connexion/security/security_handler_factory.py", line 388, in wrapper
    return function(request)
  File "/home/minhmannh2001/Documents/CodeSpace/discover_quest/user_management_service/venv/lib/python3.8/site-packages/connexion/decorators/uri_parsing.py", line 149, in wrapper
    response = function(request)
  File "/home/minhmannh2001/Documents/CodeSpace/discover_quest/user_management_service/venv/lib/python3.8/site-packages/connexion/decorators/validation.py", line 399, in wrapper
    return function(request)
  File "/home/minhmannh2001/Documents/CodeSpace/discover_quest/user_management_service/venv/lib/python3.8/site-packages/connexion/decorators/parameter.py", line 120, in wrapper
    return function(**kwargs)
  File "/home/minhmannh2001/Documents/CodeSpace/discover_quest/user_management_service/venv/lib/python3.8/site-packages/flask_jwt_extended/view_decorators.py", line 174, in decorator
    return current_app.ensure_sync(fn)(*args, **kwargs)
  File "/home/minhmannh2001/Documents/CodeSpace/discover_quest/user_management_service/app/controllers/user_controller.py", line 54, in get_user_by_id
    user = User.query.filter(
  File "/home/minhmannh2001/Documents/CodeSpace/discover_quest/user_management_service/venv/lib/python3.8/site-packages/sqlalchemy/orm/query.py", line 2743, in first
    return self.limit(1)._iter().first()  # type: ignore
  File "/home/minhmannh2001/Documents/CodeSpace/discover_quest/user_management_service/venv/lib/python3.8/site-packages/sqlalchemy/orm/query.py", line 2842, in _iter
    result: Union[ScalarResult[_T], Result[_T]] = self.session.execute(
  File "/home/minhmannh2001/Documents/CodeSpace/discover_quest/user_management_service/venv/lib/python3.8/site-packages/sqlalchemy/orm/session.py", line 2262, in execute
    return self._execute_internal(
  File "/home/minhmannh2001/Documents/CodeSpace/discover_quest/user_management_service/venv/lib/python3.8/site-packages/sqlalchemy/orm/session.py", line 2144, in _execute_internal
    result: Result[Any] = compile_state_cls.orm_execute_statement(
  File "/home/minhmannh2001/Documents/CodeSpace/discover_quest/user_management_service/venv/lib/python3.8/site-packages/sqlalchemy/orm/context.py", line 293, in orm_execute_statement
    result = conn.execute(
  File "/home/minhmannh2001/Documents/CodeSpace/discover_quest/user_management_service/venv/lib/python3.8/site-packages/sqlalchemy/engine/base.py", line 1412, in execute
    return meth(
  File "/home/minhmannh2001/Documents/CodeSpace/discover_quest/user_management_service/venv/lib/python3.8/site-packages/sqlalchemy/sql/elements.py", line 515, in _execute_on_connection
    return connection._execute_clauseelement(
  File "/home/minhmannh2001/Documents/CodeSpace/discover_quest/user_management_service/venv/lib/python3.8/site-packages/sqlalchemy/engine/base.py", line 1635, in _execute_clauseelement
    ret = self._execute_context(
  File "/home/minhmannh2001/Documents/CodeSpace/discover_quest/user_management_service/venv/lib/python3.8/site-packages/sqlalchemy/engine/base.py", line 1844, in _execute_context
    return self._exec_single_context(
  File "/home/minhmannh2001/Documents/CodeSpace/discover_quest/user_management_service/venv/lib/python3.8/site-packages/sqlalchemy/engine/base.py", line 1984, in _exec_single_context
    self._handle_dbapi_exception(
  File "/home/minhmannh2001/Documents/CodeSpace/discover_quest/user_management_service/venv/lib/python3.8/site-packages/sqlalchemy/engine/base.py", line 2339, in _handle_dbapi_exception
    raise sqlalchemy_exception.with_traceback(exc_info[2]) from e
  File "/home/minhmannh2001/Documents/CodeSpace/discover_quest/user_management_service/venv/lib/python3.8/site-packages/sqlalchemy/engine/base.py", line 1965, in _exec_single_context
    self.dialect.do_execute(
  File "/home/minhmannh2001/Documents/CodeSpace/discover_quest/user_management_service/venv/lib/python3.8/site-packages/sqlalchemy/engine/default.py", line 921, in do_execute
    cursor.execute(statement, parameters)
sqlalchemy.exc.DataError: (psycopg2.errors.InvalidTextRepresentation) invalid input syntax for type integer: "john.doe@example.com"
LINE 3: WHERE users.user_id = 'john.doe@example.com' OR users.userna...
                              ^

[SQL: SELECT users.user_id AS users_user_id, users.username AS users_username, users.email AS users_email, users.password_hash AS users_password_hash, users.created_at AS users_created_at, users.updated_at AS users_updated_at 
FROM users 
WHERE users.user_id = %(user_id_1)s OR users.username = %(username_1)s OR users.email = %(email_1)s 
 LIMIT %(param_1)s]
[parameters: {'user_id_1': 'john.doe@example.com', 'username_1': 'john.doe@example.com', 'email_1': 'john.doe@example.com', 'param_1': 1}]
(Background on this error at: https://sqlalche.me/e/20/9h9h)
2023-09-02 02:46:30,841 ERROR: Start logging API services at the error level. [in /home/minhmannh2001/Documents/CodeSpace/discover_quest/user_management_service/app/__init__.py:67]
2023-09-02 02:53:52,161 ERROR: Start logging API services at the error level. [in /home/minhmannh2001/Documents/CodeSpace/discover_quest/user_management_service/app/__init__.py:67]
2023-09-02 02:55:48,112 ERROR: Start logging API services at the error level. [in /home/minhmannh2001/Documents/CodeSpace/discover_quest/user_management_service/app/__init__.py:67]
2023-09-03 01:31:40,831 ERROR: Start logging API services at the error level. [in /home/minhmannh2001/Documents/CodeSpace/discover_quest/user_management_service/app/__init__.py:67]
2023-09-03 01:39:37,123 ERROR: Start logging API services at the error level. [in /home/minhmannh2001/Documents/CodeSpace/discover_quest/user_management_service/app/__init__.py:67]
2023-09-04 08:17:39,803 ERROR: Start logging API services at the error level. [in /home/minhmannh2001/Documents/CodeSpace/discover_quest/user_management_service/app/__init__.py:67]
2023-09-04 08:20:52,030 ERROR: Start logging API services at the error level. [in /home/minhmannh2001/Documents/CodeSpace/discover_quest/user_management_service/app/__init__.py:67]
2023-09-04 08:21:04,673 ERROR: Start logging API services at the error level. [in /home/minhmannh2001/Documents/CodeSpace/discover_quest/user_management_service/app/__init__.py:67]
2023-09-04 08:30:21,324 ERROR: Start logging API services at the error level. [in /home/minhmannh2001/Documents/CodeSpace/discover_quest/user_management_service/app/__init__.py:67]
2023-09-04 08:30:58,694 ERROR: Start logging API services at the error level. [in /home/minhmannh2001/Documents/CodeSpace/discover_quest/user_management_service/app/__init__.py:67]
2023-09-04 08:31:14,456 ERROR: Exception on /v1/users/minhmannh2001 [PUT] [in /home/minhmannh2001/Documents/CodeSpace/discover_quest/user_management_service/venv/lib/python3.8/site-packages/flask/app.py:1744]
Traceback (most recent call last):
  File "/home/minhmannh2001/Documents/CodeSpace/discover_quest/user_management_service/venv/lib/python3.8/site-packages/flask/app.py", line 2529, in wsgi_app
    response = self.full_dispatch_request()
  File "/home/minhmannh2001/Documents/CodeSpace/discover_quest/user_management_service/venv/lib/python3.8/site-packages/flask/app.py", line 1825, in full_dispatch_request
    rv = self.handle_user_exception(e)
  File "/home/minhmannh2001/Documents/CodeSpace/discover_quest/user_management_service/venv/lib/python3.8/site-packages/flask/app.py", line 1823, in full_dispatch_request
    rv = self.dispatch_request()
  File "/home/minhmannh2001/Documents/CodeSpace/discover_quest/user_management_service/venv/lib/python3.8/site-packages/flask/app.py", line 1799, in dispatch_request
    return self.ensure_sync(self.view_functions[rule.endpoint])(**view_args)
  File "/home/minhmannh2001/Documents/CodeSpace/discover_quest/user_management_service/venv/lib/python3.8/site-packages/connexion/decorators/decorator.py", line 68, in wrapper
    response = function(request)
  File "/home/minhmannh2001/Documents/CodeSpace/discover_quest/user_management_service/venv/lib/python3.8/site-packages/connexion/security/security_handler_factory.py", line 388, in wrapper
    return function(request)
  File "/home/minhmannh2001/Documents/CodeSpace/discover_quest/user_management_service/venv/lib/python3.8/site-packages/connexion/decorators/uri_parsing.py", line 149, in wrapper
    response = function(request)
  File "/home/minhmannh2001/Documents/CodeSpace/discover_quest/user_management_service/venv/lib/python3.8/site-packages/connexion/decorators/validation.py", line 196, in wrapper
    response = function(request)
  File "/home/minhmannh2001/Documents/CodeSpace/discover_quest/user_management_service/venv/lib/python3.8/site-packages/connexion/decorators/validation.py", line 399, in wrapper
    return function(request)
  File "/home/minhmannh2001/Documents/CodeSpace/discover_quest/user_management_service/venv/lib/python3.8/site-packages/connexion/decorators/parameter.py", line 120, in wrapper
    return function(**kwargs)
  File "/home/minhmannh2001/Documents/CodeSpace/discover_quest/user_management_service/venv/lib/python3.8/site-packages/flask_jwt_extended/view_decorators.py", line 174, in decorator
    return current_app.ensure_sync(fn)(*args, **kwargs)
  File "/home/minhmannh2001/Documents/CodeSpace/discover_quest/user_management_service/app/controllers/user_controller.py", line 117, in update_user
    user[key] = value
TypeError: 'User' object does not support item assignment
2023-09-04 08:34:36,516 ERROR: Start logging API services at the error level. [in /home/minhmannh2001/Documents/CodeSpace/discover_quest/user_management_service/app/__init__.py:67]
2023-09-04 08:34:48,320 ERROR: Start logging API services at the error level. [in /home/minhmannh2001/Documents/CodeSpace/discover_quest/user_management_service/app/__init__.py:67]
2023-09-04 08:37:31,404 ERROR: Start logging API services at the error level. [in /home/minhmannh2001/Documents/CodeSpace/discover_quest/user_management_service/app/__init__.py:67]
2023-09-05 21:58:13,061 ERROR: Start logging API services at the error level. [in /home/minhmannh2001/Documents/CodeSpace/discover_quest/user_management_service/app/__init__.py:67]
2023-09-09 22:11:51,245 ERROR: Start logging API services at the error level. [in /home/minhmannh2001/Documents/CodeSpace/discover_quest/user_management_service/app/__init__.py:67]
2023-09-09 22:13:48,616 ERROR: Start logging API services at the error level. [in /home/minhmannh2001/Documents/CodeSpace/discover_quest/user_management_service/app/__init__.py:67]
2023-09-09 22:23:10,437 ERROR: Start logging API services at the error level. [in /home/minhmannh2001/Documents/CodeSpace/discover_quest/user_management_service/app/__init__.py:67]
2023-09-09 22:39:43,302 ERROR: Start logging API services at the error level. [in /home/minhmannh2001/Documents/CodeSpace/discover_quest/user_management_service/app/__init__.py:68]
2023-09-09 22:39:58,227 ERROR: Start logging API services at the error level. [in /home/minhmannh2001/Documents/CodeSpace/discover_quest/user_management_service/app/__init__.py:68]
2023-09-09 22:40:15,760 ERROR: Start logging API services at the error level. [in /home/minhmannh2001/Documents/CodeSpace/discover_quest/user_management_service/app/__init__.py:68]
2023-09-09 22:41:27,372 ERROR: Start logging API services at the error level. [in /home/minhmannh2001/Documents/CodeSpace/discover_quest/user_management_service/app/__init__.py:68]
2023-09-09 22:42:32,141 ERROR: Start logging API services at the error level. [in /home/minhmannh2001/Documents/CodeSpace/discover_quest/user_management_service/app/__init__.py:68]
2023-09-09 22:44:27,391 ERROR: Start logging API services at the error level. [in /home/minhmannh2001/Documents/CodeSpace/discover_quest/user_management_service/app/__init__.py:68]
2023-09-09 22:44:33,260 ERROR: Start logging API services at the error level. [in /home/minhmannh2001/Documents/CodeSpace/discover_quest/user_management_service/app/__init__.py:68]
2023-09-09 22:45:05,654 ERROR: Start logging API services at the error level. [in /home/minhmannh2001/Documents/CodeSpace/discover_quest/user_management_service/app/__init__.py:68]
2023-09-09 22:46:03,556 ERROR: Start logging API services at the error level. [in /home/minhmannh2001/Documents/CodeSpace/discover_quest/user_management_service/app/__init__.py:68]
2023-09-09 22:46:47,571 ERROR: Start logging API services at the error level. [in /home/minhmannh2001/Documents/CodeSpace/discover_quest/user_management_service/app/__init__.py:68]
2023-09-09 22:46:54,151 ERROR: Start logging API services at the error level. [in /home/minhmannh2001/Documents/CodeSpace/discover_quest/user_management_service/app/__init__.py:68]
2023-09-09 22:49:19,120 ERROR: Start logging API services at the error level. [in /home/minhmannh2001/Documents/CodeSpace/discover_quest/user_management_service/app/__init__.py:68]
2023-09-09 22:50:49,761 ERROR: Start logging API services at the error level. [in /home/minhmannh2001/Documents/CodeSpace/discover_quest/user_management_service/app/__init__.py:68]
2023-09-09 22:56:35,361 ERROR: Start logging API services at the error level. [in /home/minhmannh2001/Documents/CodeSpace/discover_quest/user_management_service/app/__init__.py:68]
2023-09-09 22:57:37,301 ERROR: Start logging API services at the error level. [in /home/minhmannh2001/Documents/CodeSpace/discover_quest/user_management_service/app/__init__.py:68]
2023-09-09 22:58:17,143 ERROR: Start logging API services at the error level. [in /home/minhmannh2001/Documents/CodeSpace/discover_quest/user_management_service/app/__init__.py:68]
2023-09-09 22:58:56,780 ERROR: Start logging API services at the error level. [in /home/minhmannh2001/Documents/CodeSpace/discover_quest/user_management_service/app/__init__.py:68]
2023-09-09 23:01:04,843 ERROR: Start logging API services at the error level. [in /home/minhmannh2001/Documents/CodeSpace/discover_quest/user_management_service/app/__init__.py:68]
2023-09-09 23:01:25,436 ERROR: Start logging API services at the error level. [in /home/minhmannh2001/Documents/CodeSpace/discover_quest/user_management_service/app/__init__.py:68]
2023-09-10 02:53:01,338 ERROR: Start logging API services at the error level. [in /home/minhmannh2001/Documents/CodeSpace/discover_quest/user_management_service/app/__init__.py:68]
2023-09-10 03:14:56,195 ERROR: Start logging API services at the error level. [in /home/minhmannh2001/Documents/CodeSpace/discover_quest/user_management_service/app/__init__.py:68]
2023-09-16 15:08:24,226 ERROR: Start logging API services at the error level. [in /home/minhmannh2001/Documents/CodeSpace/discover_quest/user_management_service/app/__init__.py:68]
2023-09-16 15:09:01,982 ERROR: Start logging API services at the error level. [in /home/minhmannh2001/Documents/CodeSpace/discover_quest/user_management_service/app/__init__.py:68]
2023-09-16 15:10:04,529 ERROR: Start logging API services at the error level. [in /home/minhmannh2001/Documents/CodeSpace/discover_quest/user_management_service/app/__init__.py:68]
